Workbook

Sheet 2026 Outlook
A1: 2026 KEEPER OUTLOOK — 10-Team Half PPR
A2: Value = the round you'd pay to keep a player minus the round the market drafts him. Positive (green) = bargain · Negative (red) = overpay · ★ = 2025 keeper retained
A3: 2025 Team (owner) | B3: 2025 Slot | C3: Player | D3: Pos | E3: NFL Team (roster dump) | F3: 2026 ADP (half PPR) | G3: ADP Round | H3: Keeper Cost (Rd) | I3: Value (Rd) | J3: Kept in 2025 (★) | K3: Status (roster dump) | L3: ADP fallback check
A4: Allen’s Wayside Furniture (Steve) | B4: Round 1 | C4: Bijan Robinson | D4: RB | E4: ATL | F4: 2.2 | G4: =IF($F4="","",ROUNDUP($F4/10,0)) -> 1 | H4: 1 | I4: =IF($G4="","",$H4-$G4) -> 0 | J4: ★
A5: Allen’s Wayside Furniture (Steve) | B5: Round 5 | C5: Zay Flowers | D5: WR | E5: BAL | F5: 27.6 | G5: =IF($F5="","",ROUNDUP($F5/10,0)) -> 3 | H5: 5 | I5: =IF($G5="","",$H5-$G5) -> 2
A6: Allen’s Wayside Furniture (Steve) | B6: Round 2 | C6: Josh Allen | D6: QB | E6: BUF | F6: 28.3 | G6: =IF($F6="","",ROUNDUP($F6/10,0)) -> 3 | H6: 2 | I6: =IF($G6="","",$H6-$G6) -> -1
A7: Allen’s Wayside Furniture (Steve) | B7: Round 14 | C7: Kyren Williams | D7: RB | E7: LAR | F7: 30.9 | G7: =IF($F7="","",ROUNDUP($F7/10,0)) -> 4 | H7: 14 | I7: =IF($G7="","",$H7-$G7) -> 10 | J7: ★
A8: Allen’s Wayside Furniture (Steve) | B8: Round 3 | C8: Davante Adams | D8: WR | E8: LAR | F8: 38.1 | G8: =IF($F8="","",ROUNDUP($F8/10,0)) -> 4 | H8: 3 | I8: =IF($G8="","",$H8-$G8) -> -1
A9: Allen’s Wayside Furniture (Steve) | B9: Round 15 | C9: Jameson Williams | D9: WR | E9: DET | F9: 42.2 | G9: =IF($F9="","",ROUNDUP($F9/10,0)) -> 5 | H9: 15 | I9: =IF($G9="","",$H9-$G9) -> 10 | J9: ★
A10: Allen’s Wayside Furniture (Steve) | B10: Round 13 | C10: David Montgomery | D10: RB | E10: HOU | F10: 55.1 | G10: =IF($F10="","",ROUNDUP($F10/10,0)) -> 6 | H10: 13 | I10: =IF($G10="","",$H10-$G10) -> 7 | J10: ★
A11: Allen’s Wayside Furniture (Steve) | B11: Round 8 | C11: Michael Pittman Jr. | D11: WR | E11: PIT | F11: 78.7 | G11: =IF($F11="","",ROUNDUP($F11/10,0)) -> 8 | H11: 8 | I11: =IF($G11="","",$H11-$G11) -> 0
A12: Allen’s Wayside Furniture (Steve) | B12: Round 9 | C12: Tucker Kraft | D12: TE | E12: GB | F12: 79.4 | G12: =IF($F12="","",ROUNDUP($F12/10,0)) -> 8 | H12: 9 | I12: =IF($G12="","",$H12-$G12) -> 1
A13: Allen’s Wayside Furniture (Steve) | B13: Waiver add | C13: Seahawks | D13: DEF | E13: SEA | F13: 86.9 | G13: =IF($F13="","",ROUNDUP($F13/10,0)) -> 9 | H13: 15 | I13: =IF($G13="","",$H13-$G13) -> 6
A14: Allen’s Wayside Furniture (Steve) | B14: Round 4 | C14: Xavier Worthy | D14: WR | E14: KC | F14: 93.2 | G14: =IF($F14="","",ROUNDUP($F14/10,0)) -> 10 | H14: 4 | I14: =IF($G14="","",$H14-$G14) -> -6
A15: Allen’s Wayside Furniture (Steve) | B15: Round 7 | C15: Mark Andrews | D15: TE | E15: BAL | F15: 125.2 | G15: =IF($F15="","",ROUNDUP($F15/10,0)) -> 13 | H15: 7 | I15: =IF($G15="","",$H15-$G15) -> -6
A16: Allen’s Wayside Furniture (Steve) | B16: Waiver add | C16: Dalton Kincaid | D16: TE | E16: BUF | F16: 143.3 | G16: =IF($F16="","",ROUNDUP($F16/10,0)) -> 15 | H16: 15 | I16: =IF($G16="","",$H16-$G16) -> 0
A17: Allen’s Wayside Furniture (Steve) | B17: Round 12 | C17: Jake Bates | D17: K | E17: DET | F17: 150.4 | G17: =IF($F17="","",ROUNDUP($F17/10,0)) -> 16 | H17: 12 | I17: =IF($G17="","",$H17-$G17) -> -4
A18: Allen’s Wayside Furniture (Steve) | B18: Waiver add | C18: Kareem Hunt | D18: RB | E18: KC | G18: =IF($F18="","",ROUNDUP($F18/10,0)) | H18: 15 | I18: =IF($G18="","",$H18-$G18) | K18: NA | L18: Undrafted in mocks
A19: Allen’s Wayside Furniture (Steve) | B19: Waiver add | C19: Saints | D19: DEF | E19: NO | G19: =IF($F19="","",ROUNDUP($F19/10,0)) | H19: 15 | I19: =IF($G19="","",$H19-$G19)
A20: Dumpster Fire (Jon) | B20: Round 1 | C20: Jahmyr Gibbs | D20: RB | E20: DET | F20: 1.5 | G20: =IF($F20="","",ROUNDUP($F20/10,0)) -> 1 | H20: 1 | I20: =IF($G20="","",$H20-$G20) -> 0 | J20: ★
A21: Dumpster Fire (Jon) | B21: Round 2 | C21: Drake London | D21: WR | E21: ATL | F21: 12.8 | G21: =IF($F21="","",ROUNDUP($F21/10,0)) -> 2 | H21: 2 | I21: =IF($G21="","",$H21-$G21) -> 0 | J21: ★
A22: Dumpster Fire (Jon) | B22: Round 3 | C22: Kenneth Walker III | D22: RB | E22: KC | F22: 18.6 | G22: =IF($F22="","",ROUNDUP($F22/10,0)) -> 2 | H22: 3 | I22: =IF($G22="","",$H22-$G22) -> 1
A23: Dumpster Fire (Jon) | B23: Round 7 | C23: DeVonta Smith | D23: WR | E23: PHI | F23: 29.9 | G23: =IF($F23="","",ROUNDUP($F23/10,0)) -> 3 | H23: 7 | I23: =IF($G23="","",$H23-$G23) -> 4 | J23: ★
A24: Dumpster Fire (Jon) | B24: Round 5 | C24: Rome Odunze | D24: WR | E24: CHI | F24: 52.2 | G24: =IF($F24="","",ROUNDUP($F24/10,0)) -> 6 | H24: 5 | I24: =IF($G24="","",$H24-$G24) -> -1
A25: Dumpster Fire (Jon) | B25: Round 4 | C25: Tony Pollard | D25: RB | E25: TEN | F25: 69.4 | G25: =IF($F25="","",ROUNDUP($F25/10,0)) -> 7 | H25: 4 | I25: =IF($G25="","",$H25-$G25) -> -3
A26: Dumpster Fire (Jon) | B26: Round 9 | C26: Justin Herbert | D26: QB | E26: LAC | F26: 81 | G26: =IF($F26="","",ROUNDUP($F26/10,0)) -> 9 | H26: 9 | I26: =IF($G26="","",$H26-$G26) -> 0
A27: Dumpster Fire (Jon) | B27: Round 14 | C27: Wan'Dale Robinson | D27: WR | E27: TEN | F27: 98.8 | G27: =IF($F27="","",ROUNDUP($F27/10,0)) -> 10 | H27: 14 | I27: =IF($G27="","",$H27-$G27) -> 4
A28: Dumpster Fire (Jon) | B28: Waiver add | C28: Caleb Williams | D28: QB | E28: CHI | F28: 100 | G28: =IF($F28="","",ROUNDUP($F28/10,0)) -> 10 | H28: 15 | I28: =IF($G28="","",$H28-$G28) -> 5
A29: Dumpster Fire (Jon) | B29: Waiver add | C29: Kenny Gainwell | D29: RB | E29: TB | F29: 108.6 | G29: =IF($F29="","",ROUNDUP($F29/10,0)) -> 11 | H29: 15 | I29: =IF($G29="","",$H29-$G29) -> 4
A30: Dumpster Fire (Jon) | B30: Round 8 | C30: Rashid Shaheed | D30: WR | E30: SEA | F30: 120 | G30: =IF($F30="","",ROUNDUP($F30/10,0)) -> 12 | H30: 8 | I30: =IF($G30="","",$H30-$G30) -> -4
A31: Dumpster Fire (Jon) | B31: Round 6 | C31: Dallas Goedert | D31: TE | E31: PHI | F31: 128.6 | G31: =IF($F31="","",ROUNDUP($F31/10,0)) -> 13 | H31: 6 | I31: =IF($G31="","",$H31-$G31) -> -7
A32: Dumpster Fire (Jon) | B32: Waiver add | C32: Lions | D32: DEF | E32: DET | F32: 131.7 | G32: =IF($F32="","",ROUNDUP($F32/10,0)) -> 14 | H32: 15 | I32: =IF($G32="","",$H32-$G32) -> 1
A33: Dumpster Fire (Jon) | B33: Waiver add | C33: Andy Borregales | D33: K | E33: NE | F33: 146.7 | G33: =IF($F33="","",ROUNDUP($F33/10,0)) -> 15 | H33: 15 | I33: =IF($G33="","",$H33-$G33) -> 0
A34: Dumpster Fire (Jon) | B34: Waiver add | C34: Chargers | D34: DEF | E34: LAC | F34: 160.8 | G34: =IF($F34="","",ROUNDUP($F34/10,0)) -> 17 | H34: 15 | I34: =IF($G34="","",$H34-$G34) -> -2
A35: Huge Ditka (Nick) | B35: Round 1 | C35: CeeDee Lamb | D35: WR | E35: DAL | F35: 12.5 | G35: =IF($F35="","",ROUNDUP($F35/10,0)) -> 2 | H35: 1 | I35: =IF($G35="","",$H35-$G35) -> -1 | J35: ★
A36: Huge Ditka (Nick) | B36: Round 2 | C36: Malik Nabers | D36: WR | E36: NYG | F36: 48.5 | G36: =IF($F36="","",ROUNDUP($F36/10,0)) -> 5 | H36: 2 | I36: =IF($G36="","",$H36-$G36) -> -3 | J36: ★
A37: Huge Ditka (Nick) | B37: Waiver add | C37: Mike Evans | D37: WR | E37: SF | F37: 49.7 | G37: =IF($F37="","",ROUNDUP($F37/10,0)) -> 5 | H37: 15 | I37: =IF($G37="","",$H37-$G37) -> 10
A38: Huge Ditka (Nick) | B38: Waiver add | C38: DK Metcalf | D38: WR | E38: PIT | F38: 54.6 | G38: =IF($F38="","",ROUNDUP($F38/10,0)) -> 6 | H38: 15 | I38: =IF($G38="","",$H38-$G38) -> 9
A39: Huge Ditka (Nick) | B39: Round 3 | C39: TreVeyon Henderson | D39: RB | E39: NE | F39: 59.8 | G39: =IF($F39="","",ROUNDUP($F39/10,0)) -> 6 | H39: 3 | I39: =IF($G39="","",$H39-$G39) -> -3
A40: Huge Ditka (Nick) | B40: Round 4 | C40: Jaylen Warren | D40: RB | E40: PIT | F40: 65.5 | G40: =IF($F40="","",ROUNDUP($F40/10,0)) -> 7 | H40: 4 | I40: =IF($G40="","",$H40-$G40) -> -3
...

Sheet 2025 Rosters
B1: 2025 End of Year Roster and Draft Order - Not a snake draft
B2: Tom White Pool Covers | C2: Cory/Kevin Jimmy Jones Cutlets | D2: Rick Terry Glenn | E2: Nick Huge Ditka | F2: Jon Dumpster Fire | G2: Eric My Ball Zach Ertz | H2: Steve Allen’s Wayside Furniture | I2: Jordan Leeroy Judkins | J2: Mike Run CMC | K2: Ben Prestige Worldwide
A3: SPOTLIGHT → | B3: All | C3: ← pick a position; non-matching players gray out
A4: ROUND 1 | B4: Ashton Jeanty (RB - LV) | C4: Ladd McConkey (WR - LAC) | D4: James Conner (RB - Ari) | E4: CeeDee Lamb (WR - Dal) ★ | F4: Jahmyr Gibbs (RB - Det) ★ | G4: Saquon Barkley (RB - Phi) ★ | H4: Bijan Robinson (RB - Atl) ★ | I4: James Cook III (RB - Buf) | J4: Christian McCaffrey (RB - SF) ★ | K4: Omarion Hampton (RB - LAC)
A5: ROUND 2 | B5: Marvin Harrison Jr. (WR - Ari) | C5: Breece Hall (RB - NYJ) ★ | D5: Terry McLaurin (WR - Was) | E5: Malik Nabers (WR - NYG) ★ | F5: Drake London (WR - Atl) ★ | G5: DJ Moore (WR - Buf) | H5: Josh Allen (QB - Buf) | I5: Jaxon Smith-Njigba (WR - Sea) | K5: Tee Higgins (WR - Cin)
A6: ROUND 3 | C6: Alvin Kamara (RB - NO) | D6: Derrick Henry (RB - Bal) ★ | E6: TreVeyon Henderson (RB - NE) | F6: Kenneth Walker III (RB - KC) | G6: George Pickens (WR - Dal) | H6: Davante Adams (WR - LAR) | J6: Chuba Hubbard (RB - Car) | K6: Jonathan Taylor (RB - Ind) ★
A7: ROUND 4 | B7: Jaylen Waddle (WR - Den) | D7: George Kittle (TE - SF) ★ | E7: Jaylen Warren (RB - Pit) | F7: Tony Pollard (RB - Ten) | G7: Travis Hunter (WR - Jax) | H7: Xavier Worthy (WR - KC) | I7: Emeka Egbuka (WR - TB) | J7: Courtland Sutton (WR - Den) | K7: Tetairoa McMillan (WR - Car)
A8: ROUND 5 | B8: Joe Burrow (QB - Cin) | C8: Amon-Ra St. Brown (WR - Det) ★ | D8: D'Andre Swift (RB - Chi) | E8: Patrick Mahomes (QB - KC) | F8: Rome Odunze (WR - Chi) | G8: Josh Jacobs (RB - GB) ★ | H8: Zay Flowers (WR - Bal) | J8: Brock Bowers (TE - LV) ★ | K8: Ja'Marr Chase (WR - Cin) ★
A9: ROUND 6 | B9: Deebo Samuel (WR - Was) | C9: T.J. Hockenson (TE - Min) | E9: Stefon Diggs (WR - NE) | F9: Dallas Goedert (TE - Phi) | G9: Jakobi Meyers (WR - Jax) | I9: Ricky Pearsall (WR - SF) | K9: Chris Olave (WR - NO)
A10: ROUND 7 | C10: Travis Etienne Jr. (RB - NO) | F10: DeVonta Smith (WR - Phi) ★ | G10: Bo Nix (QB - Den) | H10: Mark Andrews (TE - Bal) | I10: Brian Thomas Jr. (WR - Jax) ★ | J10: Jerry Jeudy (WR - Cle) | K10: Tyler Warren (TE - Ind)
A11: ROUND 8 | C11: Jordan Mason (RB - Min) | D11: Chris Godwin Jr. (WR - TB) | F11: Rashid Shaheed (WR - Sea) | G11: Rashee Rice (WR - KC) | H11: Michael Pittman Jr. (WR - Pit) | I11: Jalen Hurts (QB - Phi) ★ | J11: Cam Skattebo (RB - NYG)
A12: ROUND 9 | B12: Justin Jefferson (WR - Min) ★ | C12: Jauan Jennings (WR - Min) | D12: Nico Collins (WR - Hou) ★ | E12: Jordan Addison (WR - Min) | F12: Justin Herbert (QB - LAC) | H12: Tucker Kraft (TE - GB) | I12: Braelon Allen (RB - NYJ) | K12: Zach Charbonnet (RB - Sea)
A13: ROUND 10 | B13: Javonte Williams (RB - Dal) | C13: Khalil Shakir (WR - Buf) | J13: De'Von Achane (RB - Mia) ★ | K13: Brandon Aubrey (K - Dal)
A14: ROUND 11 | E14: Harrison Butker (K - KC) | J14: Cameron Dicker (K - LAC)
A15: ROUND 12 | H15: Jake Bates (K - Det) | J15: Jayden Reed (WR - GB)
A16: ROUND 13 | E16: Travis Kelce (TE - KC) ★ | G16: Chase McLaughlin (K - TB) | H16: David Montgomery (RB - Hou) ★ | I16: Quinshon Judkins (RB - Cle) | K16: Rhamondre Stevenson (RB - NE)
A17: ROUND 14 | B17: Chris Boswell (K - Pit) | C17: Lamar Jackson (QB - Bal) ★ | F17: Wan'Dale Robinson (WR - Ten) | G17: Garrett Wilson (WR - NYJ) ★ | H17: Kyren Williams (RB - LAR) ★ | I17: Trey McBride (TE - Ari) ★ | J17: A.J. Brown (WR - NE) ★
A18: ROUND 15 | B18: Sam LaPorta (TE - Det) ★ | C18: Puka Nacua (WR - LAR) ★ | D18: Tyreek Hill (WR - Mia) ★ | G18: Bucky Irving (RB - TB) ★ | H18: Jameson Williams (WR - Det) ★ | I18: Chase Brown (RB - Cin) ★
B20: 2025 Waiver Wire Adds - if kept they are a last round draft pick
B21: Tom White Pool Covers | C21: Cory/Kevin Jimmy Jones Cutlets | D21: Rick Terry Glenn | E21: Nick Huge Ditka | F21: Jon Dumpster Fire | G21: Eric My Ball Zach Ertz | H21: Steve Allen’s Wayside Furniture | I21: Jordan Leeroy Judkins | J21: Mike Run CMC | K21: Ben Prestige Worldwide
A22: ADDS | B22: Zach Ertz (TE - Was) | C22: Jake Ferguson (TE - Dal) | D22: Jared Goff (QB - Det) | E22: Trevor Lawrence (QB - Jax) | F22: Caleb Williams (QB - Chi) | G22: Jayden Higgins (WR - Hou) | H22: Dalton Kincaid (TE - Buf) | I22: RJ Harvey (RB - Den) | J22: Jacoby Brissett (QB - Ari) | K22: Brock Purdy (QB - SF)
B23: Christian Watson (WR - GB) | C23: Dak Prescott (QB - Dal) | D23: Brenton Strange (TE - Jax) | E23: Mike Evans (WR - SF) | F23: Kenny Gainwell (RB - TB) | G23: Kyle Pitts Sr. (TE - Atl) | H23: Kareem Hunt (RB - KC) | I23: Kyle Monangai (RB - Chi) | J23: Michael Wilson (WR - Ari) | K23: Matthew Stafford (QB - LAR)
B24: Hunter Henry (TE - NE) | C24: Jake Elliott (K - Phi) | D24: Devin Neal (RB - NO) | E24: Rico Dowdle (RB - Pit) | F24: Andy Borregales (K - NE) | G24: Baker Mayfield (QB - TB) | H24: Saints (DEF - NO) | I24: Harold Fannin Jr. (TE - Cle) | J24: Juwan Johnson (TE - NO) | K24: Darius Slayton (WR - NYG)
B25: Drake Maye (QB - NE) | D25: Rachaad White (RB - Was) | E25: Kimani Vidal (RB - LAC) | F25: Lions (DEF - Det) | G25: Tyrone Tracy Jr. (RB - NYG) | H25: Seahawks (DEF - Sea) | I25: Jaxson Dart (QB - NYG) | J25: Blake Corum (RB - LAR) | K25: Alec Pierce (WR - Ind)
B26: Woody Marks (RB - Hou) | D26: Keenan Allen (WR - LAC) | E26: Troy Franklin (WR - Den) | F26: Chargers (DEF - LAC) | G26: Cowboys (DEF - Dal) | I26: Isaac TeSlaa (WR - Det) | J26: Michael Carter (RB - Ten) | K26: Steelers (DEF - Pit)
B27: Quentin Johnston (WR - LAC) | D27: Darnell Mooney (WR - NYG) | E27: DK Metcalf (WR - Pit) | I27: Jayden Daniels (QB - Was) | J27: Colston Loveland (TE - Chi)
B28: Jaguars (DEF - Jax) | D28: Keon Coleman (WR - Buf) | E28: Patriots (DEF - NE) | I28: Bhayshul Tuten (RB - Jax) | J28: Broncos (DEF - Den)
D29: Tyler Loop (K - Bal)
D30: Texans (DEF - Hou)
A34: ROSTER COMPOSITION (draft picks + waiver adds)
A35: Position | B35: =B$2 -> Tom White Pool Covers | C35: =C$2 -> Cory/Kevin Jimmy Jones Cutlets | D35: =D$2 -> Rick Terry Glenn | E35: =E$2 -> Nick Huge Ditka | F35: =F$2 -> Jon Dumpster Fire | G35: =G$2 -> Eric My Ball Zach Ertz | H35: =H$2 -> Steve Allen’s Wayside Furniture | I35: =I$2 -> Jordan Leeroy Judkins | ... K35: =K$2 -> Ben Prestige Worldwide
A36: QB | B36: =COUNTIF(B$4:B$18,"*("&$A36&" - *")+COUNTIF(B$22:B$31,"*("&$A36&" - *") -> 2 | C36: =COUNTIF(C$4:C$18,"*("&$A36&" - *")+COUNTIF(C$22:C$31,"*("&$A36&" - *") -> 2 | D36: =COUNTIF(D$4:D$18,"*("&$A36&" - *")+COUNTIF(D$22:D$31,"*("&$A36&" - *") -> 1 | E36: =COUNTIF(E$4:E$18,"*("&$A36&" - *")+COUNTIF(E$22:E$31,"*("&$A36&" - *") -> 2 | F36: =COUNTIF(F$4:F$18,"*("&$A36&" - *")+COUNTIF(F$22:F$31,"*("&$A36&" - *") -> 2 | G36: =COUNTIF(G$4:G$18,"*("&$A36&" - *")+COUNTIF(G$22:G$31,"*("&$A36&" - *") -> 2 | H36: =COUNTIF(H$4:H$18,"*("&$A36&" - *")+COUNTIF(H$22:H$31,"*("&$A36&" - *") -> 1 | I36: =COUNTIF(I$4:I$18,"*("&$A36&" - *")+COUNTIF(I$22:I$31,"*("&$A36&" - *") -> 3 | ... K36: =COUNTIF(K$4:K$18,"*("&$A36&" - *")+COUNTIF(K$22:K$31,"*("&$A36&" - *") -> 2
A37: RB | B37: =COUNTIF(B$4:B$18,"*("&$A37&" - *")+COUNTIF(B$22:B$31,"*("&$A37&" - *") -> 3 | C37: =COUNTIF(C$4:C$18,"*("&$A37&" - *")+COUNTIF(C$22:C$31,"*("&$A37&" - *") -> 4 | D37: =COUNTIF(D$4:D$18,"*("&$A37&" - *")+COUNTIF(D$22:D$31,"*("&$A37&" - *") -> 5 | E37: =COUNTIF(E$4:E$18,"*("&$A37&" - *")+COUNTIF(E$22:E$31,"*("&$A37&" - *") -> 4 | F37: =COUNTIF(F$4:F$18,"*("&$A37&" - *")+COUNTIF(F$22:F$31,"*("&$A37&" - *") -> 4 | G37: =COUNTIF(G$4:G$18,"*("&$A37&" - *")+COUNTIF(G$22:G$31,"*("&$A37&" - *") -> 4 | H37: =COUNTIF(H$4:H$18,"*("&$A37&" - *")+COUNTIF(H$22:H$31,"*("&$A37&" - *") -> 4 | I37: =COUNTIF(I$4:I$18,"*("&$A37&" - *")+COUNTIF(I$22:I$31,"*("&$A37&" - *") -> 7 | ... K37: =COUNTIF(K$4:K$18,"*("&$A37&" - *")+COUNTIF(K$22:K$31,"*("&$A37&" - *") -> 4
A38: WR | B38: =COUNTIF(B$4:B$18,"*("&$A38&" - *")+COUNTIF(B$22:B$31,"*("&$A38&" - *") -> 6 | C38: =COUNTIF(C$4:C$18,"*("&$A38&" - *")+COUNTIF(C$22:C$31,"*("&$A38&" - *") -> 5 | D38: =COUNTIF(D$4:D$18,"*("&$A38&" - *")+COUNTIF(D$22:D$31,"*("&$A38&" - *") -> 7 | E38: =COUNTIF(E$4:E$18,"*("&$A38&" - *")+COUNTIF(E$22:E$31,"*("&$A38&" - *") -> 7 | F38: =COUNTIF(F$4:F$18,"*("&$A38&" - *")+COUNTIF(F$22:F$31,"*("&$A38&" - *") -> 5 | G38: =COUNTIF(G$4:G$18,"*("&$A38&" - *")+COUNTIF(G$22:G$31,"*("&$A38&" - *") -> 7 | H38: =COUNTIF(H$4:H$18,"*("&$A38&" - *")+COUNTIF(H$22:H$31,"*("&$A38&" - *") -> 5 | I38: =COUNTIF(I$4:I$18,"*("&$A38&" - *")+COUNTIF(I$22:I$31,"*("&$A38&" - *") -> 5 | ... K38: =COUNTIF(K$4:K$18,"*("&$A38&" - *")+COUNTIF(K$22:K$31,"*("&$A38&" - *") -> 6
A39: TE | B39: =COUNTIF(B$4:B$18,"*("&$A39&" - *")+COUNTIF(B$22:B$31,"*("&$A39&" - *") -> 3 | C39: =COUNTIF(C$4:C$18,"*("&$A39&" - *")+COUNTIF(C$22:C$31,"*("&$A39&" - *") -> 2 | D39: =COUNTIF(D$4:D$18,"*("&$A39&" - *")+COUNTIF(D$22:D$31,"*("&$A39&" - *") -> 2 | E39: =COUNTIF(E$4:E$18,"*("&$A39&" - *")+COUNTIF(E$22:E$31,"*("&$A39&" - *") -> 1 | F39: =COUNTIF(F$4:F$18,"*("&$A39&" - *")+COUNTIF(F$22:F$31,"*("&$A39&" - *") -> 1 | G39: =COUNTIF(G$4:G$18,"*("&$A39&" - *")+COUNTIF(G$22:G$31,"*("&$A39&" - *") -> 1 | H39: =COUNTIF(H$4:H$18,"*("&$A39&" - *")+COUNTIF(H$22:H$31,"*("&$A39&" - *") -> 3 | I39: =COUNTIF(I$4:I$18,"*("&$A39&" - *")+COUNTIF(I$22:I$31,"*("&$A39&" - *") -> 2 | ... K39: =COUNTIF(K$4:K$18,"*("&$A39&" - *")+COUNTIF(K$22:K$31,"*("&$A39&" - *") -> 1
A40: K | B40: =COUNTIF(B$4:B$18,"*("&$A40&" - *")+COUNTIF(B$22:B$31,"*("&$A40&" - *") -> 1 | C40: =COUNTIF(C$4:C$18,"*("&$A40&" - *")+COUNTIF(C$22:C$31,"*("&$A40&" - *") -> 1 | D40: =COUNTIF(D$4:D$18,"*("&$A40&" - *")+COUNTIF(D$22:D$31,"*("&$A40&" - *") -> 1 | E40: =COUNTIF(E$4:E$18,"*("&$A40&" - *")+COUNTIF(E$22:E$31,"*("&$A40&" - *") -> 1 | F40: =COUNTIF(F$4:F$18,"*("&$A40&" - *")+COUNTIF(F$22:F$31,"*("&$A40&" - *") -> 1 | G40: =COUNTIF(G$4:G$18,"*("&$A40&" - *")+COUNTIF(G$22:G$31,"*("&$A40&" - *") -> 1 | H40: =COUNTIF(H$4:H$18,"*("&$A40&" - *")+COUNTIF(H$22:H$31,"*("&$A40&" - *") -> 1 | I40: =COUNTIF(I$4:I$18,"*("&$A40&" - *")+COUNTIF(I$22:I$31,"*("&$A40&" - *") -> 0 | ... K40: =COUNTIF(K$4:K$18,"*("&$A40&" - *")+COUNTIF(K$22:K$31,"*("&$A40&" - *") -> 1
A41: DEF | B41: =COUNTIF(B$4:B$18,"*("&$A41&" - *")+COUNTIF(B$22:B$31,"*("&$A41&" - *") -> 1 | C41: =COUNTIF(C$4:C$18,"*("&$A41&" - *")+COUNTIF(C$22:C$31,"*("&$A41&" - *") -> 0 | D41: =COUNTIF(D$4:D$18,"*("&$A41&" - *")+COUNTIF(D$22:D$31,"*("&$A41&" - *") -> 1 | E41: =COUNTIF(E$4:E$18,"*("&$A41&" - *")+COUNTIF(E$22:E$31,"*("&$A41&" - *") -> 1 | F41: =COUNTIF(F$4:F$18,"*("&$A41&" - *")+COUNTIF(F$22:F$31,"*("&$A41&" - *") -> 2 | G41: =COUNTIF(G$4:G$18,"*("&$A41&" - *")+COUNTIF(G$22:G$31,"*("&$A41&" - *") -> 1 | H41: =COUNTIF(H$4:H$18,"*("&$A41&" - *")+COUNTIF(H$22:H$31,"*("&$A41&" - *") -> 2 | I41: =COUNTIF(I$4:I$18,"*("&$A41&" - *")+COUNTIF(I$22:I$31,"*("&$A41&" - *") -> 0 | ... K41: =COUNTIF(K$4:K$18,"*("&$A41&" - *")+COUNTIF(K$22:K$31,"*("&$A41&" - *") -> 1
A42: Total players | B42: =SUM(B$36:B$41) -> 16 | C42: =SUM(C$36:C$41) -> 14 | D42: =SUM(D$36:D$41) -> 17 | E42: =SUM(E$36:E$41) -> 16 | F42: =SUM(F$36:F$41) -> 15 | G42: =SUM(G$36:G$41) -> 16 | H42: =SUM(H$36:H$41) -> 16 | I42: =SUM(I$36:I$41) -> 17 | ... K42: =SUM(K$36:K$41) -> 15
A43: ★ 2025 keepers kept | B43: =COUNTIF(B$4:B$18,"*★*") -> 2 | C43: =COUNTIF(C$4:C$18,"*★*") -> 4 | D43: =COUNTIF(D$4:D$18,"*★*") -> 4 | E43: =COUNTIF(E$4:E$18,"*★*") -> 3 | F43: =COUNTIF(F$4:F$18,"*★*") -> 3 | G43: =COUNTIF(G$4:G$18,"*★*") -> 4 | H43: =COUNTIF(H$4:H$18,"*★*") -> 4 | I43: =COUNTIF(I$4:I$18,"*★*") -> 4 | ... K43: =COUNTIF(K$4:K$18,"*★*") -> 2
A45: LEGEND
...

Sheet Allen's Wayside Furniture
A1: ALLEN’S WAYSIDE FURNITURE — Steve
A2: ='2026 Outlook'!B3 -> 2025 Slot | B2: ='2026 Outlook'!C3 -> Player | C2: ='2026 Outlook'!D3 -> Pos | D2: ='2026 Outlook'!E3 -> NFL Team (roster dump) | E2: ='2026 Outlook'!F3 -> 2026 ADP (half PPR) | F2: ='2026 Outlook'!G3 -> ADP Round | G2: ='2026 Outlook'!H3 -> Keeper Cost (Rd) | H2: ='2026 Outlook'!I3 -> Value (Rd) | ... K2: ='2026 Outlook'!L3 -> ADP fallback check | M2: TEAM SUMMARY
A3: {=_xlfn.LET(_xlpm.r,_xlfn._xlws.FILTER('2026 Outlook'!$B$4:$L$162,'2026 Outlook'!$A$4:$A$162=$N$11,"no players"),_xlpm.s,_xlfn.SORTBY(_xlpm.r,MATCH(INDEX(_xlpm.r,0,3),{"QB";"RB";"WR";"TE";"K";"DEF"},0),1,INDEX(_xlpm.r,0,5),1),IF(_xlpm.s="","",_xlpm.s))} -> Round 2 | B3: Josh Allen | C3: QB | D3: BUF | E3: 28.3 | F3: 3 | G3: 2 | H3: -1 | M3: Players | N3: =COUNTIFS('2026 Outlook'!$A$4:$A$162,$N$11) -> 16
A4: Round 1 | B4: Bijan Robinson | C4: RB | D4: ATL | E4: 2.2 | F4: 1 | G4: 1 | H4: 0 | I4: ★ | M4: ★ Kept in 2025 | N4: =COUNTIFS('2026 Outlook'!$A$4:$A$162,$N$11,'2026 Outlook'!$J$4:$J$162,"★") -> 4
A5: Round 14 | B5: Kyren Williams | C5: RB | D5: LAR | E5: 30.9 | F5: 4 | G5: 14 | H5: 10 | I5: ★ | M5: Avg ADP | N5: =IFERROR(AVERAGEIFS('2026 Outlook'!$F$4:$F$162,'2026 Outlook'!$A$4:$A$162,$N$11),"—") -> 70.107143
A6: Round 13 | B6: David Montgomery | C6: RB | D6: HOU | E6: 55.1 | F6: 6 | G6: 13 | H6: 7 | I6: ★ | M6: Best value (Rd) | N6: =IFERROR(_xlfn.MAXIFS('2026 Outlook'!$I$4:$I$162,'2026 Outlook'!$A$4:$A$162,$N$11),"—") -> 10
A7: Waiver add | B7: Kareem Hunt | C7: RB | D7: KC | G7: 15 | J7: NA | K7: Undrafted in mocks | M7: Best value player | N7: {=IFERROR(INDEX('2026 Outlook'!$C$4:$C$162,MATCH(1,('2026 Outlook'!$A$4:$A$162=$N$11)*('2026 Outlook'!$I$4:$I$162=$N$6),0)),"—")} -> Kyren Williams
A8: Round 5 | B8: Zay Flowers | C8: WR | D8: BAL | E8: 27.6 | F8: 3 | G8: 5 | H8: 2 | M8: Players with no ADP | N8: =COUNTIFS('2026 Outlook'!$A$4:$A$162,$N$11,'2026 Outlook'!$F$4:$F$162,"") -> 2
A9: Round 3 | B9: Davante Adams | C9: WR | D9: LAR | E9: 38.1 | F9: 4 | G9: 3 | H9: -1 | M9: Status flags | N9: =COUNTIFS('2026 Outlook'!$A$4:$A$162,$N$11,'2026 Outlook'!$K$4:$K$162,"<>") -> 1
A10: Round 15 | B10: Jameson Williams | C10: WR | D10: DET | E10: 42.2 | F10: 5 | G10: 15 | H10: 10 | I10: ★
A11: Round 8 | B11: Michael Pittman Jr. | C11: WR | D11: PIT | E11: 78.7 | F11: 8 | G11: 8 | H11: 0 | M11: Team key (do not edit) | N11: Allen’s Wayside Furniture (Steve)
A12: Round 4 | B12: Xavier Worthy | C12: WR | D12: KC | E12: 93.2 | F12: 10 | G12: 4 | H12: -6
A13: Round 9 | B13: Tucker Kraft | C13: TE | D13: GB | E13: 79.4 | F13: 8 | G13: 9 | H13: 1
A14: Round 7 | B14: Mark Andrews | C14: TE | D14: BAL | E14: 125.2 | F14: 13 | G14: 7 | H14: -6
A15: Waiver add | B15: Dalton Kincaid | C15: TE | D15: BUF | E15: 143.3 | F15: 15 | G15: 15 | H15: 0
A16: Round 12 | B16: Jake Bates | C16: K | D16: DET | E16: 150.4 | F16: 16 | G16: 12 | H16: -4
A17: Waiver add | B17: Seahawks | C17: DEF | D17: SEA | E17: 86.9 | F17: 9 | G17: 15 | H17: 6
A18: Waiver add | B18: Saints | C18: DEF | D18: NO | G18: 15
A20: POSITION COUNTS
A21: QB | B21: =COUNTIFS('2026 Outlook'!$A$4:$A$162,$N$11,'2026 Outlook'!$D$4:$D$162,"QB") -> 1
A22: RB | B22: =COUNTIFS('2026 Outlook'!$A$4:$A$162,$N$11,'2026 Outlook'!$D$4:$D$162,"RB") -> 4
A23: WR | B23: =COUNTIFS('2026 Outlook'!$A$4:$A$162,$N$11,'2026 Outlook'!$D$4:$D$162,"WR") -> 5
A24: TE | B24: =COUNTIFS('2026 Outlook'!$A$4:$A$162,$N$11,'2026 Outlook'!$D$4:$D$162,"TE") -> 3
A25: K | B25: =COUNTIFS('2026 Outlook'!$A$4:$A$162,$N$11,'2026 Outlook'!$D$4:$D$162,"K") -> 1
A26: DEF | B26: =COUNTIFS('2026 Outlook'!$A$4:$A$162,$N$11,'2026 Outlook'!$D$4:$D$162,"DEF") -> 2
A27: TOTAL | B27: =SUM(B21:B26) -> 16

Sheet Dumpster Fire
A1: DUMPSTER FIRE — Joe
A2: ='2026 Outlook'!B3 -> 2025 Slot | B2: ='2026 Outlook'!C3 -> Player | C2: ='2026 Outlook'!D3 -> Pos | D2: ='2026 Outlook'!E3 -> NFL Team (roster dump) | E2: ='2026 Outlook'!F3 -> 2026 ADP (half PPR) | F2: ='2026 Outlook'!G3 -> ADP Round | G2: ='2026 Outlook'!H3 -> Keeper Cost (Rd) | H2: ='2026 Outlook'!I3 -> Value (Rd) | ... K2: ='2026 Outlook'!L3 -> ADP fallback check | M2: TEAM SUMMARY
A3: {=_xlfn.LET(_xlpm.r,_xlfn._xlws.FILTER('2026 Outlook'!$B$4:$L$162,'2026 Outlook'!$A$4:$A$162=$N$11,"no players"),_xlpm.s,_xlfn.SORTBY(_xlpm.r,MATCH(INDEX(_xlpm.r,0,3),{"QB";"RB";"WR";"TE";"K";"DEF"},0),1,INDEX(_xlpm.r,0,5),1),IF(_xlpm.s="","",_xlpm.s))} -> Round 9 | B3: Justin Herbert | C3: QB | D3: LAC | E3: 81 | F3: 9 | G3: 9 | H3: 0 | M3: Players | N3: =COUNTIFS('2026 Outlook'!$A$4:$A$162,$N$11) -> 15
A4: Waiver add | B4: Caleb Williams | C4: QB | D4: CHI | E4: 100 | F4: 10 | G4: 15 | H4: 5 | M4: ★ Kept in 2025 | N4: =COUNTIFS('2026 Outlook'!$A$4:$A$162,$N$11,'2026 Outlook'!$J$4:$J$162,"★") -> 3
A5: Round 1 | B5: Jahmyr Gibbs | C5: RB | D5: DET | E5: 1.5 | F5: 1 | G5: 1 | H5: 0 | I5: ★ | M5: Avg ADP | N5: =IFERROR(AVERAGEIFS('2026 Outlook'!$F$4:$F$162,'2026 Outlook'!$A$4:$A$162,$N$11),"—") -> 84.04
A6: Round 3 | B6: Kenneth Walker III | C6: RB | D6: KC | E6: 18.6 | F6: 2 | G6: 3 | H6: 1 | M6: Best value (Rd) | N6: =IFERROR(_xlfn.MAXIFS('2026 Outlook'!$I$4:$I$162,'2026 Outlook'!$A$4:$A$162,$N$11),"—") -> 5
A7: Round 4 | B7: Tony Pollard | C7: RB | D7: TEN | E7: 69.4 | F7: 7 | G7: 4 | H7: -3 | M7: Best value player | N7: {=IFERROR(INDEX('2026 Outlook'!$C$4:$C$162,MATCH(1,('2026 Outlook'!$A$4:$A$162=$N$11)*('2026 Outlook'!$I$4:$I$162=$N$6),0)),"—")} -> Caleb Williams
A8: Waiver add | B8: Kenny Gainwell | C8: RB | D8: TB | E8: 108.6 | F8: 11 | G8: 15 | H8: 4 | M8: Players with no ADP | N8: =COUNTIFS('2026 Outlook'!$A$4:$A$162,$N$11,'2026 Outlook'!$F$4:$F$162,"") -> 0
A9: Round 2 | B9: Drake London | C9: WR | D9: ATL | E9: 12.8 | F9: 2 | G9: 2 | H9: 0 | I9: ★ | M9: Status flags | N9: =COUNTIFS('2026 Outlook'!$A$4:$A$162,$N$11,'2026 Outlook'!$K$4:$K$162,"<>") -> 0
A10: Round 7 | B10: DeVonta Smith | C10: WR | D10: PHI | E10: 29.9 | F10: 3 | G10: 7 | H10: 4 | I10: ★
A11: Round 5 | B11: Rome Odunze | C11: WR | D11: CHI | E11: 52.2 | F11: 6 | G11: 5 | H11: -1 | M11: Team key (do not edit) | N11: Dumpster Fire (Jon)
A12: Round 14 | B12: Wan'Dale Robinson | C12: WR | D12: TEN | E12: 98.8 | F12: 10 | G12: 14 | H12: 4
A13: Round 8 | B13: Rashid Shaheed | C13: WR | D13: SEA | E13: 120 | F13: 12 | G13: 8 | H13: -4
A14: Round 6 | B14: Dallas Goedert | C14: TE | D14: PHI | E14: 128.6 | F14: 13 | G14: 6 | H14: -7
A15: Waiver add | B15: Andy Borregales | C15: K | D15: NE | E15: 146.7 | F15: 15 | G15: 15 | H15: 0
A16: Waiver add | B16: Lions | C16: DEF | D16: DET | E16: 131.7 | F16: 14 | G16: 15 | H16: 1
A17: Waiver add | B17: Chargers | C17: DEF | D17: LAC | E17: 160.8 | F17: 17 | G17: 15 | H17: -2
A19: POSITION COUNTS
A20: QB | B20: =COUNTIFS('2026 Outlook'!$A$4:$A$162,$N$11,'2026 Outlook'!$D$4:$D$162,"QB") -> 2
A21: RB | B21: =COUNTIFS('2026 Outlook'!$A$4:$A$162,$N$11,'2026 Outlook'!$D$4:$D$162,"RB") -> 4
A22: WR | B22: =COUNTIFS('2026 Outlook'!$A$4:$A$162,$N$11,'2026 Outlook'!$D$4:$D$162,"WR") -> 5
A23: TE | B23: =COUNTIFS('2026 Outlook'!$A$4:$A$162,$N$11,'2026 Outlook'!$D$4:$D$162,"TE") -> 1
A24: K | B24: =COUNTIFS('2026 Outlook'!$A$4:$A$162,$N$11,'2026 Outlook'!$D$4:$D$162,"K") -> 1
A25: DEF | B25: =COUNTIFS('2026 Outlook'!$A$4:$A$162,$N$11,'2026 Outlook'!$D$4:$D$162,"DEF") -> 2
A26: TOTAL | B26: =SUM(B20:B25) -> 15

Sheet Huge Ditka
A1: HUGE DITKA — Nick
A2: ='2026 Outlook'!B3 -> 2025 Slot | B2: ='2026 Outlook'!C3 -> Player | C2: ='2026 Outlook'!D3 -> Pos | D2: ='2026 Outlook'!E3 -> NFL Team (roster dump) | E2: ='2026 Outlook'!F3 -> 2026 ADP (half PPR) | F2: ='2026 Outlook'!G3 -> ADP Round | G2: ='2026 Outlook'!H3 -> Keeper Cost (Rd) | H2: ='2026 Outlook'!I3 -> Value (Rd) | ... K2: ='2026 Outlook'!L3 -> ADP fallback check | M2: TEAM SUMMARY
A3: {=_xlfn.LET(_xlpm.r,_xlfn._xlws.FILTER('2026 Outlook'!$B$4:$L$162,'2026 Outlook'!$A$4:$A$162=$N$11,"no players"),_xlpm.s,_xlfn.SORTBY(_xlpm.r,MATCH(INDEX(_xlpm.r,0,3),{"QB";"RB";"WR";"TE";"K";"DEF"},0),1,INDEX(_xlpm.r,0,5),1),IF(_xlpm.s="","",_xlpm.s))} -> Round 5 | B3: Patrick Mahomes | C3: QB | D3: KC | E3: 82.6 | F3: 9 | G3: 5 | H3: -4 | M3: Players | N3: =COUNTIFS('2026 Outlook'!$A$4:$A$162,$N$11) -> 16
A4: Waiver add | B4: Trevor Lawrence | C4: QB | D4: JAX | E4: 83.7 | F4: 9 | G4: 15 | H4: 6 | M4: ★ Kept in 2025 | N4: =COUNTIFS('2026 Outlook'!$A$4:$A$162,$N$11,'2026 Outlook'!$J$4:$J$162,"★") -> 3
A5: Round 3 | B5: TreVeyon Henderson | C5: RB | D5: NE | E5: 59.8 | F5: 6 | G5: 3 | H5: -3 | M5: Avg ADP | N5: =IFERROR(AVERAGEIFS('2026 Outlook'!$F$4:$F$162,'2026 Outlook'!$A$4:$A$162,$N$11),"—") -> 83.95
A6: Round 4 | B6: Jaylen Warren | C6: RB | D6: PIT | E6: 65.5 | F6: 7 | G6: 4 | H6: -3 | M6: Best value (Rd) | N6: =IFERROR(_xlfn.MAXIFS('2026 Outlook'!$I$4:$I$162,'2026 Outlook'!$A$4:$A$162,$N$11),"—") -> 10
A7: Waiver add | B7: Rico Dowdle | C7: RB | D7: PIT | E7: 78.5 | F7: 8 | G7: 15 | H7: 7 | M7: Best value player | N7: {=IFERROR(INDEX('2026 Outlook'!$C$4:$C$162,MATCH(1,('2026 Outlook'!$A$4:$A$162=$N$11)*('2026 Outlook'!$I$4:$I$162=$N$6),0)),"—")} -> Mike Evans
A8: Waiver add | B8: Kimani Vidal | C8: RB | D8: LAC | G8: 15 | K8: Undrafted in mocks | M8: Players with no ADP | N8: =COUNTIFS('2026 Outlook'!$A$4:$A$162,$N$11,'2026 Outlook'!$F$4:$F$162,"") -> 2
A9: Round 1 | B9: CeeDee Lamb | C9: WR | D9: DAL | E9: 12.5 | F9: 2 | G9: 1 | H9: -1 | I9: ★ | M9: Status flags | N9: =COUNTIFS('2026 Outlook'!$A$4:$A$162,$N$11,'2026 Outlook'!$K$4:$K$162,"<>") -> 1
A10: Round 2 | B10: Malik Nabers | C10: WR | D10: NYG | E10: 48.5 | F10: 5 | G10: 2 | H10: -3 | I10: ★
A11: Waiver add | B11: Mike Evans | C11: WR | D11: SF | E11: 49.7 | F11: 5 | G11: 15 | H11: 10 | M11: Team key (do not edit) | N11: Huge Ditka (Nick)
A12: Waiver add | B12: DK Metcalf | C12: WR | D12: PIT | E12: 54.6 | F12: 6 | G12: 15 | H12: 9
A13: Round 9 | B13: Jordan Addison | C13: WR | D13: MIN | E13: 88.5 | F13: 9 | G13: 9 | H13: 0
A14: Waiver add | B14: Troy Franklin | C14: WR | D14: DEN | E14: 182.7 | F14: 19 | G14: 15 | H14: -4
A15: Round 6 | B15: Stefon Diggs | C15: WR | D15: NE | G15: 6 | J15: NA | K15: Undrafted in mocks
A16: Round 13 | B16: Travis Kelce | C16: TE | D16: KC | E16: 96.4 | F16: 10 | G16: 13 | H16: 3 | I16: ★
A17: Round 11 | B17: Harrison Butker | C17: K | D17: KC | E17: 164.5 | F17: 17 | G17: 11 | H17: -6
A18: Waiver add | B18: Patriots | C18: DEF | D18: NE | E18: 107.8 | F18: 11 | G18: 15 | H18: 4
A20: POSITION COUNTS
A21: QB | B21: =COUNTIFS('2026 Outlook'!$A$4:$A$162,$N$11,'2026 Outlook'!$D$4:$D$162,"QB") -> 2
A22: RB | B22: =COUNTIFS('2026 Outlook'!$A$4:$A$162,$N$11,'2026 Outlook'!$D$4:$D$162,"RB") -> 4
A23: WR | B23: =COUNTIFS('2026 Outlook'!$A$4:$A$162,$N$11,'2026 Outlook'!$D$4:$D$162,"WR") -> 7
A24: TE | B24: =COUNTIFS('2026 Outlook'!$A$4:$A$162,$N$11,'2026 Outlook'!$D$4:$D$162,"TE") -> 1
A25: K | B25: =COUNTIFS('2026 Outlook'!$A$4:$A$162,$N$11,'2026 Outlook'!$D$4:$D$162,"K") -> 1
A26: DEF | B26: =COUNTIFS('2026 Outlook'!$A$4:$A$162,$N$11,'2026 Outlook'!$D$4:$D$162,"DEF") -> 1
A27: TOTAL | B27: =SUM(B21:B26) -> 16

Sheet Jimmy Jones Cutlets
A1: JIMMY JONES CUTLETS — Cory/Kevin
A2: ='2026 Outlook'!B3 -> 2025 Slot | B2: ='2026 Outlook'!C3 -> Player | C2: ='2026 Outlook'!D3 -> Pos | D2: ='2026 Outlook'!E3 -> NFL Team (roster dump) | E2: ='2026 Outlook'!F3 -> 2026 ADP (half PPR) | F2: ='2026 Outlook'!G3 -> ADP Round | G2: ='2026 Outlook'!H3 -> Keeper Cost (Rd) | H2: ='2026 Outlook'!I3 -> Value (Rd) | ... K2: ='2026 Outlook'!L3 -> ADP fallback check | M2: TEAM SUMMARY
A3: {=_xlfn.LET(_xlpm.r,_xlfn._xlws.FILTER('2026 Outlook'!$B$4:$L$162,'2026 Outlook'!$A$4:$A$162=$N$11,"no players"),_xlpm.s,_xlfn.SORTBY(_xlpm.r,MATCH(INDEX(_xlpm.r,0,3),{"QB";"RB";"WR";"TE";"K";"DEF"},0),1,INDEX(_xlpm.r,0,5),1),IF(_xlpm.s="","",_xlpm.s))} -> Round 14 | B3: Lamar Jackson | C3: QB | D3: BAL | E3: 54.6 | F3: 6 | G3: 14 | H3: 8 | I3: ★ | M3: Players | N3: =COUNTIFS('2026 Outlook'!$A$4:$A$162,$N$11) -> 14
A4: Waiver add | B4: Dak Prescott | C4: QB | D4: DAL | E4: 58.5 | F4: 6 | G4: 15 | H4: 9 | M4: ★ Kept in 2025 | N4: =COUNTIFS('2026 Outlook'!$A$4:$A$162,$N$11,'2026 Outlook'!$J$4:$J$162,"★") -> 4
A5: Round 2 | B5: Breece Hall | C5: RB | D5: NYJ | E5: 30.4 | F5: 4 | G5: 2 | H5: -2 | I5: ★ | M5: Avg ADP | N5: =IFERROR(AVERAGEIFS('2026 Outlook'!$F$4:$F$162,'2026 Outlook'!$A$4:$A$162,$N$11),"—") -> 77.746154
A6: Round 7 | B6: Travis Etienne Jr. | C6: RB | D6: NO | E6: 37.5 | F6: 4 | G6: 7 | H6: 3 | M6: Best value (Rd) | N6: =IFERROR(_xlfn.MAXIFS('2026 Outlook'!$I$4:$I$162,'2026 Outlook'!$A$4:$A$162,$N$11),"—") -> 14
A7: Round 8 | B7: Jordan Mason | C7: RB | D7: MIN | E7: 120.1 | F7: 13 | G7: 8 | H7: -5 | M7: Best value player | N7: {=IFERROR(INDEX('2026 Outlook'!$C$4:$C$162,MATCH(1,('2026 Outlook'!$A$4:$A$162=$N$11)*('2026 Outlook'!$I$4:$I$162=$N$6),0)),"—")} -> Puka Nacua
A8: Round 3 | B8: Alvin Kamara | C8: RB | D8: NO | E8: 151.9 | F8: 16 | G8: 3 | H8: -13 | M8: Players with no ADP | N8: =COUNTIFS('2026 Outlook'!$A$4:$A$162,$N$11,'2026 Outlook'!$F$4:$F$162,"") -> 1
A9: Round 15 | B9: Puka Nacua | C9: WR | D9: LAR | E9: 2.9 | F9: 1 | G9: 15 | H9: 14 | I9: ★ | M9: Status flags | N9: =COUNTIFS('2026 Outlook'!$A$4:$A$162,$N$11,'2026 Outlook'!$K$4:$K$162,"<>") -> 0
A10: Round 5 | B10: Amon-Ra St. Brown | C10: WR | D10: DET | E10: 8.2 | F10: 1 | G10: 5 | H10: 4 | I10: ★
A11: Round 1 | B11: Ladd McConkey | C11: WR | D11: LAC | E11: 36 | F11: 4 | G11: 1 | H11: -3 | M11: Team key (do not edit) | N11: Jimmy Jones Cutlets (Cory/Kevin)
A12: Round 10 | B12: Khalil Shakir | C12: WR | D12: BUF | E12: 105.8 | F12: 11 | G12: 10 | H12: -1
A13: Round 9 | B13: Jauan Jennings | C13: WR | D13: MIN | E13: 130.7 | F13: 14 | G13: 9 | H13: -5
A14: Waiver add | B14: Jake Ferguson | C14: TE | D14: DAL | E14: 126.3 | F14: 13 | G14: 15 | H14: 2
A15: Round 6 | B15: T.J. Hockenson | C15: TE | D15: MIN | E15: 147.8 | F15: 15 | G15: 6 | H15: -9
A16: Waiver add | B16: Jake Elliott | C16: K | D16: PHI | G16: 15 | K16: Undrafted in mocks
A18: POSITION COUNTS
A19: QB | B19: =COUNTIFS('2026 Outlook'!$A$4:$A$162,$N$11,'2026 Outlook'!$D$4:$D$162,"QB") -> 2
A20: RB | B20: =COUNTIFS('2026 Outlook'!$A$4:$A$162,$N$11,'2026 Outlook'!$D$4:$D$162,"RB") -> 4
A21: WR | B21: =COUNTIFS('2026 Outlook'!$A$4:$A$162,$N$11,'2026 Outlook'!$D$4:$D$162,"WR") -> 5
A22: TE | B22: =COUNTIFS('2026 Outlook'!$A$4:$A$162,$N$11,'2026 Outlook'!$D$4:$D$162,"TE") -> 2
A23: K | B23: =COUNTIFS('2026 Outlook'!$A$4:$A$162,$N$11,'2026 Outlook'!$D$4:$D$162,"K") -> 1
A24: DEF | B24: =COUNTIFS('2026 Outlook'!$A$4:$A$162,$N$11,'2026 Outlook'!$D$4:$D$162,"DEF") -> 0
A25: TOTAL | B25: =SUM(B19:B24) -> 14

Sheet Leeroy Judkins
A1: LEEROY JUDKINS — Jordan
A2: ='2026 Outlook'!B3 -> 2025 Slot | B2: ='2026 Outlook'!C3 -> Player | C2: ='2026 Outlook'!D3 -> Pos | D2: ='2026 Outlook'!E3 -> NFL Team (roster dump) | E2: ='2026 Outlook'!F3 -> 2026 ADP (half PPR) | F2: ='2026 Outlook'!G3 -> ADP Round | G2: ='2026 Outlook'!H3 -> Keeper Cost (Rd) | H2: ='2026 Outlook'!I3 -> Value (Rd) | ... K2: ='2026 Outlook'!L3 -> ADP fallback check | M2: TEAM SUMMARY
A3: {=_xlfn.LET(_xlpm.r,_xlfn._xlws.FILTER('2026 Outlook'!$B$4:$L$162,'2026 Outlook'!$A$4:$A$162=$N$11,"no players"),_xlpm.s,_xlfn.SORTBY(_xlpm.r,MATCH(INDEX(_xlpm.r,0,3),{"QB";"RB";"WR";"TE";"K";"DEF"},0),1,INDEX(_xlpm.r,0,5),1),IF(_xlpm.s="","",_xlpm.s))} -> Waiver add | B3: Jayden Daniels | C3: QB | D3: WAS | E3: 80.6 | F3: 9 | G3: 15 | H3: 6 | M3: Players | N3: =COUNTIFS('2026 Outlook'!$A$4:$A$162,$N$11) -> 17
A4: Round 8 | B4: Jalen Hurts | C4: QB | D4: PHI | E4: 93.9 | F4: 10 | G4: 8 | H4: -2 | I4: ★ | M4: ★ Kept in 2025 | N4: =COUNTIFS('2026 Outlook'!$A$4:$A$162,$N$11,'2026 Outlook'!$J$4:$J$162,"★") -> 4
A5: Waiver add | B5: Jaxson Dart | C5: QB | D5: NYG | E5: 121.2 | F5: 13 | G5: 15 | H5: 2 | M5: Avg ADP | N5: =IFERROR(AVERAGEIFS('2026 Outlook'!$F$4:$F$162,'2026 Outlook'!$A$4:$A$162,$N$11),"—") -> 70.28125
A6: Round 1 | B6: James Cook III | C6: RB | D6: BUF | E6: 10.3 | F6: 2 | G6: 1 | H6: -1 | M6: Best value (Rd) | N6: =IFERROR(_xlfn.MAXIFS('2026 Outlook'!$I$4:$I$162,'2026 Outlook'!$A$4:$A$162,$N$11),"—") -> 12
A7: Round 15 | B7: Chase Brown | C7: RB | D7: CIN | E7: 20.1 | F7: 3 | G7: 15 | H7: 12 | I7: ★ | M7: Best value player | N7: {=IFERROR(INDEX('2026 Outlook'!$C$4:$C$162,MATCH(1,('2026 Outlook'!$A$4:$A$162=$N$11)*('2026 Outlook'!$I$4:$I$162=$N$6),0)),"—")} -> Chase Brown
A8: Round 13 | B8: Quinshon Judkins | C8: RB | D8: CLE | E8: 47.7 | F8: 5 | G8: 13 | H8: 8 | M8: Players with no ADP | N8: =COUNTIFS('2026 Outlook'!$A$4:$A$162,$N$11,'2026 Outlook'!$F$4:$F$162,"") -> 1
A9: Waiver add | B9: Bhayshul Tuten | C9: RB | D9: JAX | E9: 57 | F9: 6 | G9: 15 | H9: 9 | M9: Status flags | N9: =COUNTIFS('2026 Outlook'!$A$4:$A$162,$N$11,'2026 Outlook'!$K$4:$K$162,"<>") -> 0
A10: Waiver add | B10: RJ Harvey | C10: RB | D10: DEN | E10: 97.6 | F10: 10 | G10: 15 | H10: 5
A11: Waiver add | B11: Kyle Monangai | C11: RB | D11: CHI | E11: 98.8 | F11: 10 | G11: 15 | H11: 5 | M11: Team key (do not edit) | N11: Leeroy Judkins (Jordan)
A12: Round 9 | B12: Braelon Allen | C12: RB | D12: NYJ | G12: 9 | K12: 12-tm full-PPR ADP 171.2
A13: Round 2 | B13: Jaxon Smith-Njigba | C13: WR | D13: SEA | E13: 7.1 | F13: 1 | G13: 2 | H13: 1
A14: Round 4 | B14: Emeka Egbuka | C14: WR | D14: TB | E14: 44.5 | F14: 5 | G14: 4 | H14: -1
A15: Round 7 | B15: Brian Thomas Jr. | C15: WR | D15: JAX | E15: 74.6 | F15: 8 | G15: 7 | H15: -1 | I15: ★
A16: Round 6 | B16: Ricky Pearsall | C16: WR | D16: SF | E16: 98.6 | F16: 10 | G16: 6 | H16: -4
A17: Waiver add | B17: Isaac TeSlaa | C17: WR | D17: DET | E17: 155.4 | F17: 16 | G17: 15 | H17: -1
A18: Round 14 | B18: Trey McBride | C18: TE | D18: ARI | E18: 37.5 | F18: 4 | G18: 14 | H18: 10 | I18: ★
A19: Waiver add | B19: Harold Fannin Jr. | C19: TE | D19: CLE | E19: 79.6 | F19: 8 | G19: 15 | H19: 7
A21: POSITION COUNTS
A22: QB | B22: =COUNTIFS('2026 Outlook'!$A$4:$A$162,$N$11,'2026 Outlook'!$D$4:$D$162,"QB") -> 3
A23: RB | B23: =COUNTIFS('2026 Outlook'!$A$4:$A$162,$N$11,'2026 Outlook'!$D$4:$D$162,"RB") -> 7
A24: WR | B24: =COUNTIFS('2026 Outlook'!$A$4:$A$162,$N$11,'2026 Outlook'!$D$4:$D$162,"WR") -> 5
A25: TE | B25: =COUNTIFS('2026 Outlook'!$A$4:$A$162,$N$11,'2026 Outlook'!$D$4:$D$162,"TE") -> 2
A26: K | B26: =COUNTIFS('2026 Outlook'!$A$4:$A$162,$N$11,'2026 Outlook'!$D$4:$D$162,"K") -> 0
A27: DEF | B27: =COUNTIFS('2026 Outlook'!$A$4:$A$162,$N$11,'2026 Outlook'!$D$4:$D$162,"DEF") -> 0
A28: TOTAL | B28: =SUM(B22:B27) -> 17

Sheet My Ball Zach Ertz
A1: MY BALL ZACH ERTZ — Eric
A2: ='2026 Outlook'!B3 -> 2025 Slot | B2: ='2026 Outlook'!C3 -> Player | C2: ='2026 Outlook'!D3 -> Pos | D2: ='2026 Outlook'!E3 -> NFL Team (roster dump) | E2: ='2026 Outlook'!F3 -> 2026 ADP (half PPR) | F2: ='2026 Outlook'!G3 -> ADP Round | G2: ='2026 Outlook'!H3 -> Keeper Cost (Rd) | H2: ='2026 Outlook'!I3 -> Value (Rd) | ... K2: ='2026 Outlook'!L3 -> ADP fallback check | M2: TEAM SUMMARY
A3: {=_xlfn.LET(_xlpm.r,_xlfn._xlws.FILTER('2026 Outlook'!$B$4:$L$162,'2026 Outlook'!$A$4:$A$162=$N$11,"no players"),_xlpm.s,_xlfn.SORTBY(_xlpm.r,MATCH(INDEX(_xlpm.r,0,3),{"QB";"RB";"WR";"TE";"K";"DEF"},0),1,INDEX(_xlpm.r,0,5),1),IF(_xlpm.s="","",_xlpm.s))} -> Round 7 | B3: Bo Nix | C3: QB | D3: DEN | E3: 120.2 | F3: 13 | G3: 7 | H3: -6 | M3: Players | N3: =COUNTIFS('2026 Outlook'!$A$4:$A$162,$N$11) -> 16
A4: Waiver add | B4: Baker Mayfield | C4: QB | D4: TB | E4: 131.6 | F4: 14 | G4: 15 | H4: 1 | M4: ★ Kept in 2025 | N4: =COUNTIFS('2026 Outlook'!$A$4:$A$162,$N$11,'2026 Outlook'!$J$4:$J$162,"★") -> 4
A5: Round 1 | B5: Saquon Barkley | C5: RB | D5: PHI | E5: 16.7 | F5: 2 | G5: 1 | H5: -1 | I5: ★ | M5: Avg ADP | N5: =IFERROR(AVERAGEIFS('2026 Outlook'!$F$4:$F$162,'2026 Outlook'!$A$4:$A$162,$N$11),"—") -> 87.35625
A6: Round 5 | B6: Josh Jacobs | C6: RB | D6: GB | E6: 24.7 | F6: 3 | G6: 5 | H6: 2 | I6: ★ | M6: Best value (Rd) | N6: =IFERROR(_xlfn.MAXIFS('2026 Outlook'!$I$4:$I$162,'2026 Outlook'!$A$4:$A$162,$N$11),"—") -> 10
A7: Round 15 | B7: Bucky Irving | C7: RB | D7: TB | E7: 46.1 | F7: 5 | G7: 15 | H7: 10 | I7: ★ | M7: Best value player | N7: {=IFERROR(INDEX('2026 Outlook'!$C$4:$C$162,MATCH(1,('2026 Outlook'!$A$4:$A$162=$N$11)*('2026 Outlook'!$I$4:$I$162=$N$6),0)),"—")} -> Garrett Wilson
A8: Waiver add | B8: Tyrone Tracy Jr. | C8: RB | D8: NYG | E8: 156.1 | F8: 16 | G8: 15 | H8: -1 | M8: Players with no ADP | N8: =COUNTIFS('2026 Outlook'!$A$4:$A$162,$N$11,'2026 Outlook'!$F$4:$F$162,"") -> 0
A9: Round 3 | B9: George Pickens | C9: WR | D9: DAL | E9: 19.2 | F9: 2 | G9: 3 | H9: 1 | M9: Status flags | N9: =COUNTIFS('2026 Outlook'!$A$4:$A$162,$N$11,'2026 Outlook'!$K$4:$K$162,"<>") -> 0
A10: Round 8 | B10: Rashee Rice | C10: WR | D10: KC | E10: 27 | F10: 3 | G10: 8 | H10: 5
A11: Round 14 | B11: Garrett Wilson | C11: WR | D11: NYJ | E11: 30.8 | F11: 4 | G11: 14 | H11: 10 | I11: ★ | M11: Team key (do not edit) | N11: My Ball Zach Ertz (Eric)
A12: Round 2 | B12: DJ Moore | C12: WR | D12: BUF | E12: 66 | F12: 7 | G12: 2 | H12: -5
A13: Round 6 | B13: Jakobi Meyers | C13: WR | D13: JAX | E13: 98.3 | F13: 10 | G13: 6 | H13: -4
A14: Waiver add | B14: Jayden Higgins | C14: WR | D14: HOU | E14: 113.6 | F14: 12 | G14: 15 | H14: 3
A15: Round 4 | B15: Travis Hunter | C15: WR | D15: JAX | E15: 160.9 | F15: 17 | G15: 4 | H15: -13
A16: Waiver add | B16: Kyle Pitts Sr. | C16: TE | D16: ATL | E16: 88.5 | F16: 9 | G16: 15 | H16: 6
A17: Round 13 | B17: Chase McLaughlin | C17: K | D17: TB | E17: 164.4 | F17: 17 | G17: 13 | H17: -4
A18: Waiver add | B18: Cowboys | C18: DEF | D18: DAL | E18: 133.6 | F18: 14 | G18: 15 | H18: 1
A20: POSITION COUNTS
A21: QB | B21: =COUNTIFS('2026 Outlook'!$A$4:$A$162,$N$11,'2026 Outlook'!$D$4:$D$162,"QB") -> 2
A22: RB | B22: =COUNTIFS('2026 Outlook'!$A$4:$A$162,$N$11,'2026 Outlook'!$D$4:$D$162,"RB") -> 4
A23: WR | B23: =COUNTIFS('2026 Outlook'!$A$4:$A$162,$N$11,'2026 Outlook'!$D$4:$D$162,"WR") -> 7
A24: TE | B24: =COUNTIFS('2026 Outlook'!$A$4:$A$162,$N$11,'2026 Outlook'!$D$4:$D$162,"TE") -> 1
A25: K | B25: =COUNTIFS('2026 Outlook'!$A$4:$A$162,$N$11,'2026 Outlook'!$D$4:$D$162,"K") -> 1
A26: DEF | B26: =COUNTIFS('2026 Outlook'!$A$4:$A$162,$N$11,'2026 Outlook'!$D$4:$D$162,"DEF") -> 1
A27: TOTAL | B27: =SUM(B21:B26) -> 16

Sheet Prestige Worldwide
A1: PRESTIGE WORLDWIDE — Ben
A2: ='2026 Outlook'!B3 -> 2025 Slot | B2: ='2026 Outlook'!C3 -> Player | C2: ='2026 Outlook'!D3 -> Pos | D2: ='2026 Outlook'!E3 -> NFL Team (roster dump) | E2: ='2026 Outlook'!F3 -> 2026 ADP (half PPR) | F2: ='2026 Outlook'!G3 -> ADP Round | G2: ='2026 Outlook'!H3 -> Keeper Cost (Rd) | H2: ='2026 Outlook'!I3 -> Value (Rd) | ... K2: ='2026 Outlook'!L3 -> ADP fallback check | M2: TEAM SUMMARY
A3: {=_xlfn.LET(_xlpm.r,_xlfn._xlws.FILTER('2026 Outlook'!$B$4:$L$162,'2026 Outlook'!$A$4:$A$162=$N$11,"no players"),_xlpm.s,_xlfn.SORTBY(_xlpm.r,MATCH(INDEX(_xlpm.r,0,3),{"QB";"RB";"WR";"TE";"K";"DEF"},0),1,INDEX(_xlpm.r,0,5),1),IF(_xlpm.s="","",_xlpm.s))} -> Waiver add | B3: Brock Purdy | C3: QB | D3: SF | E3: 101.4 | F3: 11 | G3: 15 | H3: 4 | M3: Players | N3: =COUNTIFS('2026 Outlook'!$A$4:$A$162,$N$11) -> 15
A4: Waiver add | B4: Matthew Stafford | C4: QB | D4: LAR | E4: 102.3 | F4: 11 | G4: 15 | H4: 4 | M4: ★ Kept in 2025 | N4: =COUNTIFS('2026 Outlook'!$A$4:$A$162,$N$11,'2026 Outlook'!$J$4:$J$162,"★") -> 2
A5: Round 3 | B5: Jonathan Taylor | C5: RB | D5: IND | E5: 6.1 | F5: 1 | G5: 3 | H5: 2 | I5: ★ | M5: Avg ADP | N5: =IFERROR(AVERAGEIFS('2026 Outlook'!$F$4:$F$162,'2026 Outlook'!$A$4:$A$162,$N$11),"—") -> 67.035714
A6: Round 1 | B6: Omarion Hampton | C6: RB | D6: LAC | E6: 17.2 | F6: 2 | G6: 1 | H6: -1 | M6: Best value (Rd) | N6: =IFERROR(_xlfn.MAXIFS('2026 Outlook'!$I$4:$I$162,'2026 Outlook'!$A$4:$A$162,$N$11),"—") -> 9
A7: Round 13 | B7: Rhamondre Stevenson | C7: RB | D7: NE | E7: 74.3 | F7: 8 | G7: 13 | H7: 5 | M7: Best value player | N7: {=IFERROR(INDEX('2026 Outlook'!$C$4:$C$162,MATCH(1,('2026 Outlook'!$A$4:$A$162=$N$11)*('2026 Outlook'!$I$4:$I$162=$N$6),0)),"—")} -> Alec Pierce
A8: Round 9 | B8: Zach Charbonnet | C8: RB | D8: SEA | E8: 151.9 | F8: 16 | G8: 9 | H8: -7 | J8: PUP-P | M8: Players with no ADP | N8: =COUNTIFS('2026 Outlook'!$A$4:$A$162,$N$11,'2026 Outlook'!$F$4:$F$162,"") -> 1
A9: Round 5 | B9: Ja'Marr Chase | C9: WR | D9: CIN | E9: 4.4 | F9: 1 | G9: 5 | H9: 4 | I9: ★ | M9: Status flags | N9: =COUNTIFS('2026 Outlook'!$A$4:$A$162,$N$11,'2026 Outlook'!$K$4:$K$162,"<>") -> 1
A10: Round 6 | B10: Chris Olave | C10: WR | D10: NO | E10: 23.4 | F10: 3 | G10: 6 | H10: 3
A11: Round 2 | B11: Tee Higgins | C11: WR | D11: CIN | E11: 25.4 | F11: 3 | G11: 2 | H11: -1 | M11: Team key (do not edit) | N11: Prestige Worldwide (Ben)
A12: Round 4 | B12: Tetairoa McMillan | C12: WR | D12: CAR | E12: 35.2 | F12: 4 | G12: 4 | H12: 0
A13: Waiver add | B13: Alec Pierce | C13: WR | D13: IND | E13: 59.8 | F13: 6 | G13: 15 | H13: 9
A14: Waiver add | B14: Darius Slayton | C14: WR | D14: NYG | G14: 15 | K14: 12-tm full-PPR ADP 180.3
A15: Round 7 | B15: Tyler Warren | C15: TE | D15: IND | E15: 61.3 | F15: 7 | G15: 7 | H15: 0
A16: Round 10 | B16: Brandon Aubrey | C16: K | D16: DAL | E16: 128.7 | F16: 13 | G16: 10 | H16: -3
A17: Waiver add | B17: Steelers | C17: DEF | D17: PIT | E17: 147.1 | F17: 15 | G17: 15 | H17: 0
A19: POSITION COUNTS
A20: QB | B20: =COUNTIFS('2026 Outlook'!$A$4:$A$162,$N$11,'2026 Outlook'!$D$4:$D$162,"QB") -> 2
A21: RB | B21: =COUNTIFS('2026 Outlook'!$A$4:$A$162,$N$11,'2026 Outlook'!$D$4:$D$162,"RB") -> 4
A22: WR | B22: =COUNTIFS('2026 Outlook'!$A$4:$A$162,$N$11,'2026 Outlook'!$D$4:$D$162,"WR") -> 6
A23: TE | B23: =COUNTIFS('2026 Outlook'!$A$4:$A$162,$N$11,'2026 Outlook'!$D$4:$D$162,"TE") -> 1
A24: K | B24: =COUNTIFS('2026 Outlook'!$A$4:$A$162,$N$11,'2026 Outlook'!$D$4:$D$162,"K") -> 1
A25: DEF | B25: =COUNTIFS('2026 Outlook'!$A$4:$A$162,$N$11,'2026 Outlook'!$D$4:$D$162,"DEF") -> 1
A26: TOTAL | B26: =SUM(B20:B25) -> 15

Sheet Run CMC
A1: RUN CMC — Mike
A2: ='2026 Outlook'!B3 -> 2025 Slot | B2: ='2026 Outlook'!C3 -> Player | C2: ='2026 Outlook'!D3 -> Pos | D2: ='2026 Outlook'!E3 -> NFL Team (roster dump) | E2: ='2026 Outlook'!F3 -> 2026 ADP (half PPR) | F2: ='2026 Outlook'!G3 -> ADP Round | G2: ='2026 Outlook'!H3 -> Keeper Cost (Rd) | H2: ='2026 Outlook'!I3 -> Value (Rd) | ... K2: ='2026 Outlook'!L3 -> ADP fallback check | M2: TEAM SUMMARY
A3: {=_xlfn.LET(_xlpm.r,_xlfn._xlws.FILTER('2026 Outlook'!$B$4:$L$162,'2026 Outlook'!$A$4:$A$162=$N$11,"no players"),_xlpm.s,_xlfn.SORTBY(_xlpm.r,MATCH(INDEX(_xlpm.r,0,3),{"QB";"RB";"WR";"TE";"K";"DEF"},0),1,INDEX(_xlpm.r,0,5),1),IF(_xlpm.s="","",_xlpm.s))} -> Waiver add | B3: Jacoby Brissett | C3: QB | D3: ARI | G3: 15 | K3: Undrafted in mocks | M3: Players | N3: =COUNTIFS('2026 Outlook'!$A$4:$A$162,$N$11) -> 17
A4: Round 1 | B4: Christian McCaffrey | C4: RB | D4: SF | E4: 5.1 | F4: 1 | G4: 1 | H4: 0 | I4: ★ | M4: ★ Kept in 2025 | N4: =COUNTIFS('2026 Outlook'!$A$4:$A$162,$N$11,'2026 Outlook'!$J$4:$J$162,"★") -> 4
A5: Round 10 | B5: De'Von Achane | C5: RB | D5: MIA | E5: 9.7 | F5: 1 | G5: 10 | H5: 9 | I5: ★ | M5: Avg ADP | N5: =IFERROR(AVERAGEIFS('2026 Outlook'!$F$4:$F$162,'2026 Outlook'!$A$4:$A$162,$N$11),"—") -> 76.666667
A6: Round 8 | B6: Cam Skattebo | C6: RB | D6: NYG | E6: 35.2 | F6: 4 | G6: 8 | H6: 4 | M6: Best value (Rd) | N6: =IFERROR(_xlfn.MAXIFS('2026 Outlook'!$I$4:$I$162,'2026 Outlook'!$A$4:$A$162,$N$11),"—") -> 12
A7: Round 3 | B7: Chuba Hubbard | C7: RB | D7: CAR | E7: 81.6 | F7: 9 | G7: 3 | H7: -6 | M7: Best value player | N7: {=IFERROR(INDEX('2026 Outlook'!$C$4:$C$162,MATCH(1,('2026 Outlook'!$A$4:$A$162=$N$11)*('2026 Outlook'!$I$4:$I$162=$N$6),0)),"—")} -> A.J. Brown
A8: Waiver add | B8: Blake Corum | C8: RB | D8: LAR | E8: 115 | F8: 12 | G8: 15 | H8: 3 | M8: Players with no ADP | N8: =COUNTIFS('2026 Outlook'!$A$4:$A$162,$N$11,'2026 Outlook'!$F$4:$F$162,"") -> 2
A9: Waiver add | B9: Michael Carter | C9: RB | D9: TEN | G9: 15 | K9: Undrafted in mocks | M9: Status flags | N9: =COUNTIFS('2026 Outlook'!$A$4:$A$162,$N$11,'2026 Outlook'!$K$4:$K$162,"<>") -> 0
A10: Round 14 | B10: A.J. Brown | C10: WR | D10: NE | E10: 16.2 | F10: 2 | G10: 14 | H10: 12 | I10: ★
A11: Round 4 | B11: Courtland Sutton | C11: WR | D11: DEN | E11: 69.4 | F11: 7 | G11: 4 | H11: -3 | M11: Team key (do not edit) | N11: Run CMC (Mike)
A12: Waiver add | B12: Michael Wilson | C12: WR | D12: ARI | E12: 81.4 | F12: 9 | G12: 15 | H12: 6
A13: Round 12 | B13: Jayden Reed | C13: WR | D13: GB | E13: 81.8 | F13: 9 | G13: 12 | H13: 3
A14: Round 7 | B14: Jerry Jeudy | C14: WR | D14: CLE | E14: 138.6 | F14: 14 | G14: 7 | H14: -7
A15: Round 5 | B15: Brock Bowers | C15: TE | D15: LV | E15: 44.1 | F15: 5 | G15: 5 | H15: 0 | I15: ★
A16: Waiver add | B16: Colston Loveland | C16: TE | D16: CHI | E16: 52.6 | F16: 6 | G16: 15 | H16: 9
A17: Waiver add | B17: Juwan Johnson | C17: TE | D17: NO | E17: 171.2 | F17: 18 | G17: 15 | H17: -3
A18: Round 11 | B18: Cameron Dicker | C18: K | D18: LAC | E18: 147.6 | F18: 15 | G18: 11 | H18: -4
A19: Waiver add | B19: Broncos | C19: DEF | D19: DEN | E19: 100.5 | F19: 11 | G19: 15 | H19: 4
A21: POSITION COUNTS
A22: QB | B22: =COUNTIFS('2026 Outlook'!$A$4:$A$162,$N$11,'2026 Outlook'!$D$4:$D$162,"QB") -> 1
A23: RB | B23: =COUNTIFS('2026 Outlook'!$A$4:$A$162,$N$11,'2026 Outlook'!$D$4:$D$162,"RB") -> 6
A24: WR | B24: =COUNTIFS('2026 Outlook'!$A$4:$A$162,$N$11,'2026 Outlook'!$D$4:$D$162,"WR") -> 5
A25: TE | B25: =COUNTIFS('2026 Outlook'!$A$4:$A$162,$N$11,'2026 Outlook'!$D$4:$D$162,"TE") -> 3
A26: K | B26: =COUNTIFS('2026 Outlook'!$A$4:$A$162,$N$11,'2026 Outlook'!$D$4:$D$162,"K") -> 1
A27: DEF | B27: =COUNTIFS('2026 Outlook'!$A$4:$A$162,$N$11,'2026 Outlook'!$D$4:$D$162,"DEF") -> 1
A28: TOTAL | B28: =SUM(B22:B27) -> 17

Sheet Terry Glenn
A1: TERRY GLENN — Rick
A2: ='2026 Outlook'!B3 -> 2025 Slot | B2: ='2026 Outlook'!C3 -> Player | C2: ='2026 Outlook'!D3 -> Pos | D2: ='2026 Outlook'!E3 -> NFL Team (roster dump) | E2: ='2026 Outlook'!F3 -> 2026 ADP (half PPR) | F2: ='2026 Outlook'!G3 -> ADP Round | G2: ='2026 Outlook'!H3 -> Keeper Cost (Rd) | H2: ='2026 Outlook'!I3 -> Value (Rd) | ... K2: ='2026 Outlook'!L3 -> ADP fallback check | M2: TEAM SUMMARY
A3: {=_xlfn.LET(_xlpm.r,_xlfn._xlws.FILTER('2026 Outlook'!$B$4:$L$162,'2026 Outlook'!$A$4:$A$162=$N$11,"no players"),_xlpm.s,_xlfn.SORTBY(_xlpm.r,MATCH(INDEX(_xlpm.r,0,3),{"QB";"RB";"WR";"TE";"K";"DEF"},0),1,INDEX(_xlpm.r,0,5),1),IF(_xlpm.s="","",_xlpm.s))} -> Waiver add | B3: Jared Goff | C3: QB | D3: DET | E3: 94.3 | F3: 10 | G3: 15 | H3: 5 | M3: Players | N3: =COUNTIFS('2026 Outlook'!$A$4:$A$162,$N$11) -> 17
A4: Round 3 | B4: Derrick Henry | C4: RB | D4: BAL | E4: 9.9 | F4: 1 | G4: 3 | H4: 2 | I4: ★ | M4: ★ Kept in 2025 | N4: =COUNTIFS('2026 Outlook'!$A$4:$A$162,$N$11,'2026 Outlook'!$J$4:$J$162,"★") -> 4
A5: Round 5 | B5: D'Andre Swift | C5: RB | D5: CHI | E5: 45.8 | F5: 5 | G5: 5 | H5: 0 | M5: Avg ADP | N5: =IFERROR(AVERAGEIFS('2026 Outlook'!$F$4:$F$162,'2026 Outlook'!$A$4:$A$162,$N$11),"—") -> 82.481818
A6: Waiver add | B6: Rachaad White | C6: RB | D6: WAS | E6: 111.3 | F6: 12 | G6: 15 | H6: 3 | M6: Best value (Rd) | N6: =IFERROR(_xlfn.MAXIFS('2026 Outlook'!$I$4:$I$162,'2026 Outlook'!$A$4:$A$162,$N$11),"—") -> 6
A7: Round 1 | B7: James Conner | C7: RB | D7: ARI | G7: 1 | K7: Undrafted in mocks | M7: Best value player | N7: {=IFERROR(INDEX('2026 Outlook'!$C$4:$C$162,MATCH(1,('2026 Outlook'!$A$4:$A$162=$N$11)*('2026 Outlook'!$I$4:$I$162=$N$6),0)),"—")} -> Nico Collins
A8: Waiver add | B8: Devin Neal | C8: RB | D8: NO | G8: 15 | K8: Undrafted in mocks | M8: Players with no ADP | N8: =COUNTIFS('2026 Outlook'!$A$4:$A$162,$N$11,'2026 Outlook'!$F$4:$F$162,"") -> 6
A9: Round 9 | B9: Nico Collins | C9: WR | D9: HOU | E9: 23.8 | F9: 3 | G9: 9 | H9: 6 | I9: ★ | M9: Status flags | N9: =COUNTIFS('2026 Outlook'!$A$4:$A$162,$N$11,'2026 Outlook'!$K$4:$K$162,"<>") -> 3
A10: Round 2 | B10: Terry McLaurin | C10: WR | D10: WAS | E10: 36.7 | F10: 4 | G10: 2 | H10: -2
A11: Round 8 | B11: Chris Godwin Jr. | C11: WR | D11: TB | E11: 81.5 | F11: 9 | G11: 8 | H11: -1 | M11: Team key (do not edit) | N11: Terry Glenn (Rick)
A12: Round 15 | B12: Tyreek Hill | C12: WR | D12: MIA | G12: 15 | I12: ★ | J12: NA | K12: Undrafted in mocks
A13: Waiver add | B13: Keenan Allen | C13: WR | D13: LAC | G13: 15 | J13: NA | K13: Undrafted in mocks
A14: Waiver add | B14: Darnell Mooney | C14: WR | D14: NYG | G14: 15 | K14: Undrafted in mocks
A15: Waiver add | B15: Keon Coleman | C15: WR | D15: BUF | G15: 15 | K15: Undrafted in mocks
A16: Round 4 | B16: George Kittle | C16: TE | D16: SF | E16: 104.2 | F16: 11 | G16: 4 | H16: -7 | I16: ★ | J16: PUP-P
A17: Waiver add | B17: Brenton Strange | C17: TE | D17: JAX | E17: 143.9 | F17: 15 | G17: 15 | H17: 0
A18: Waiver add | B18: Tyler Loop | C18: K | D18: BAL | E18: 148.2 | F18: 15 | G18: 15 | H18: 0
A19: Waiver add | B19: Texans | C19: DEF | D19: HOU | E19: 107.7 | F19: 11 | G19: 15 | H19: 4
A21: POSITION COUNTS
A22: QB | B22: =COUNTIFS('2026 Outlook'!$A$4:$A$162,$N$11,'2026 Outlook'!$D$4:$D$162,"QB") -> 1
A23: RB | B23: =COUNTIFS('2026 Outlook'!$A$4:$A$162,$N$11,'2026 Outlook'!$D$4:$D$162,"RB") -> 5
A24: WR | B24: =COUNTIFS('2026 Outlook'!$A$4:$A$162,$N$11,'2026 Outlook'!$D$4:$D$162,"WR") -> 7
A25: TE | B25: =COUNTIFS('2026 Outlook'!$A$4:$A$162,$N$11,'2026 Outlook'!$D$4:$D$162,"TE") -> 2
A26: K | B26: =COUNTIFS('2026 Outlook'!$A$4:$A$162,$N$11,'2026 Outlook'!$D$4:$D$162,"K") -> 1
A27: DEF | B27: =COUNTIFS('2026 Outlook'!$A$4:$A$162,$N$11,'2026 Outlook'!$D$4:$D$162,"DEF") -> 1
A28: TOTAL | B28: =SUM(B22:B27) -> 17

Sheet White Pool Covers
A1: WHITE POOL COVERS — Tom
A2: ='2026 Outlook'!B3 -> 2025 Slot | B2: ='2026 Outlook'!C3 -> Player | C2: ='2026 Outlook'!D3 -> Pos | D2: ='2026 Outlook'!E3 -> NFL Team (roster dump) | E2: ='2026 Outlook'!F3 -> 2026 ADP (half PPR) | F2: ='2026 Outlook'!G3 -> ADP Round | G2: ='2026 Outlook'!H3 -> Keeper Cost (Rd) | H2: ='2026 Outlook'!I3 -> Value (Rd) | ... K2: ='2026 Outlook'!L3 -> ADP fallback check | M2: TEAM SUMMARY
A3: {=_xlfn.LET(_xlpm.r,_xlfn._xlws.FILTER('2026 Outlook'!$B$4:$L$162,'2026 Outlook'!$A$4:$A$162=$N$11,"no players"),_xlpm.s,_xlfn.SORTBY(_xlpm.r,MATCH(INDEX(_xlpm.r,0,3),{"QB";"RB";"WR";"TE";"K";"DEF"},0),1,INDEX(_xlpm.r,0,5),1),IF(_xlpm.s="","",_xlpm.s))} -> Round 5 | B3: Joe Burrow | C3: QB | D3: CIN | E3: 48.3 | F3: 5 | G3: 5 | H3: 0 | M3: Players | N3: =COUNTIFS('2026 Outlook'!$A$4:$A$162,$N$11) -> 16
A4: Waiver add | B4: Drake Maye | C4: QB | D4: NE | E4: 62.8 | F4: 7 | G4: 15 | H4: 8 | M4: ★ Kept in 2025 | N4: =COUNTIFS('2026 Outlook'!$A$4:$A$162,$N$11,'2026 Outlook'!$J$4:$J$162,"★") -> 2
A5: Round 1 | B5: Ashton Jeanty | C5: RB | D5: LV | E5: 13.6 | F5: 2 | G5: 1 | H5: -1 | M5: Avg ADP | N5: =IFERROR(AVERAGEIFS('2026 Outlook'!$F$4:$F$162,'2026 Outlook'!$A$4:$A$162,$N$11),"—") -> 79.342857
A6: Round 10 | B6: Javonte Williams | C6: RB | D6: DAL | E6: 32.4 | F6: 4 | G6: 10 | H6: 6 | M6: Best value (Rd) | N6: =IFERROR(_xlfn.MAXIFS('2026 Outlook'!$I$4:$I$162,'2026 Outlook'!$A$4:$A$162,$N$11),"—") -> 9
A7: Waiver add | B7: Woody Marks | C7: RB | D7: HOU | E7: 147.3 | F7: 15 | G7: 15 | H7: 0 | M7: Best value player | N7: {=IFERROR(INDEX('2026 Outlook'!$C$4:$C$162,MATCH(1,('2026 Outlook'!$A$4:$A$162=$N$11)*('2026 Outlook'!$I$4:$I$162=$N$6),0)),"—")} -> Christian Watson
A8: Round 9 | B8: Justin Jefferson | C8: WR | D8: MIN | E8: 13.5 | F8: 2 | G8: 9 | H8: 7 | I8: ★ | M8: Players with no ADP | N8: =COUNTIFS('2026 Outlook'!$A$4:$A$162,$N$11,'2026 Outlook'!$F$4:$F$162,"") -> 2
A9: Round 4 | B9: Jaylen Waddle | C9: WR | D9: DEN | E9: 38.5 | F9: 4 | G9: 4 | H9: 0 | M9: Status flags | N9: =COUNTIFS('2026 Outlook'!$A$4:$A$162,$N$11,'2026 Outlook'!$K$4:$K$162,"<>") -> 2
A10: Waiver add | B10: Christian Watson | C10: WR | D10: GB | E10: 59.1 | F10: 6 | G10: 15 | H10: 9
A11: Round 2 | B11: Marvin Harrison Jr. | C11: WR | D11: ARI | E11: 64.9 | F11: 7 | G11: 2 | H11: -5 | M11: Team key (do not edit) | N11: White Pool Covers (Tom)
A12: Waiver add | B12: Quentin Johnston | C12: WR | D12: LAC | E12: 89.9 | F12: 9 | G12: 15 | H12: 6
A13: Round 6 | B13: Deebo Samuel | C13: WR | D13: WAS | G13: 6 | J13: NA | K13: Undrafted in mocks
A14: Round 15 | B14: Sam LaPorta | C14: TE | D14: DET | E14: 80.8 | F14: 9 | G14: 15 | H14: 6 | I14: ★
A15: Waiver add | B15: Hunter Henry | C15: TE | D15: NE | E15: 148.1 | F15: 15 | G15: 15 | H15: 0
A16: Waiver add | B16: Zach Ertz | C16: TE | D16: WAS | G16: 15 | J16: NA | K16: Undrafted in mocks
A17: Round 14 | B17: Chris Boswell | C17: K | D17: PIT | E17: 179.4 | F17: 18 | G17: 14 | H17: -4
A18: Waiver add | B18: Jaguars | C18: DEF | D18: JAX | E18: 132.2 | F18: 14 | G18: 15 | H18: 1
A20: POSITION COUNTS
A21: QB | B21: =COUNTIFS('2026 Outlook'!$A$4:$A$162,$N$11,'2026 Outlook'!$D$4:$D$162,"QB") -> 2
A22: RB | B22: =COUNTIFS('2026 Outlook'!$A$4:$A$162,$N$11,'2026 Outlook'!$D$4:$D$162,"RB") -> 3
A23: WR | B23: =COUNTIFS('2026 Outlook'!$A$4:$A$162,$N$11,'2026 Outlook'!$D$4:$D$162,"WR") -> 6
A24: TE | B24: =COUNTIFS('2026 Outlook'!$A$4:$A$162,$N$11,'2026 Outlook'!$D$4:$D$162,"TE") -> 3
A25: K | B25: =COUNTIFS('2026 Outlook'!$A$4:$A$162,$N$11,'2026 Outlook'!$D$4:$D$162,"K") -> 1
A26: DEF | B26: =COUNTIFS('2026 Outlook'!$A$4:$A$162,$N$11,'2026 Outlook'!$D$4:$D$162,"DEF") -> 1
A27: TOTAL | B27: =SUM(B21:B26) -> 16

Sheet 2025 Draft Results
B1: 2025 Roster Results
B2: Nick Huge Ditka | C2: Tom White Pool Covers | D2: Steve Bed Bath & Bijan | E2: Jon Dumpster Fire | F2: Cory/Kevin Jimmy Jones Cutlets | G2: Ben Prestige Worldwide | H2: Jordan JR | I2: Mike Run CMC | J2: Rick Terry Glenn | K2: Eric My Ball Zach Ertz
A3: ROUND 1 | B3: CeeDee Lamb | C3: Ashton Jeanty | D3: Bijan Robinson | E3: Jahmyr Gibbs | F3: Ladd McConkey | G3: Omarion Hampton | H3: James Cook III | I3: Christian McCaffrey | J3: James Conner | K3: Saquon Barkley
A4: ROUND 2 | B4: Malik Nabers | C4: Marvin Harrison | D4: Josh Allen | E4: Drake London | F4: Breece Hall | G4: Tee Higgins | H4: Jaxon Smith-Njigba | I4: Mike Evans | J4: Terry McLaurin | K4: DJ Moore
A5: ROUND 3 | B5: TreVeyon Henderson | C5: Isiah Pacheco | D5: Davante Adams | E5: Kevin Walker III | F5: Alvin Kamara | G5: Jonathan Taylor | H5: DK Metcalf | I5: Chuba Hubbard | J5: Derrick Henry | K5: George Pickens
A6: ROUND 4 | B6: Jaylen Warren | C6: Jaylen Waddle | D6: Xavier Worthy | E6: Tony Pollard | F6: RJ Harvey | G6: Tetairoa McMillan | H6: Emeka Egbuka | I6: Courtland Sutton | J6: George Kittle | K6: Travis Hunter
A7: ROUND 5 | B7: Patrick Mahomes | C7: Joe Burrow | D7: Zay Flowers | E7: Rome Odunze | F7: Amon-Ra St. Brown | G7: Ja'Marr Chase | H7: Kaleb Johnson | I7: Brock Bowers | J7: D'Andre Swift | K7: Josh Jacobs
A8: ROUND 6 | B8: Stefon Diggs | C8: Deebo Samuel | D8: Tyrone Tracy Jr. | E8: Dallas Goedert | F8: T.J Hockenson | G8: Chris Olave | H8: Ricky Pearsall | I8: Kyler Murray | J8: Evan Engram | K8: Jakobi Meyers
A9: ROUND 7 | B9: Aaron Jones Sr. | C9: Matthew Golden | D9: Mark Andrews | E9: DeVonta Smith | F9: Travis Etienne | G9: Tyler Warren | H9: Brian Thomas Jr. | I9: Jerry Jeudy | J9: Brock Purdy | K9: Bo Nix
A10: ROUND 8 | B10: Cooper Kupp | C10: Keon Coleman | D10: Michael Pittman Jr | E10: Rashid Shaheed | F10: Jordan Mason | G10: Jayden Daniels | H10: Jalen Hurts | I10: Cam Skattebo | J10: Chris Godwin Jr | K10: Rashee Rice
A11: ROUND 9 | B11: Jordan Addison | C11: Justin Jefferson | D11: Tucker Kraft | E11: Justin Herbert | F11: Jauan Jennings | G11: Zach Charbonnet | H11: Braelon Allen | I11: Joe Mixon | J11: Nico Collin | K11: J.K Dobbins
A12: ROUND 10 | B12: C.J Stroud | C12: Javonte Williams | D12: Rashod Bateman | E12: Tank Bigsby | F12: Khalil Shakir | G12: Brandon Aubrey | H12: Jacory Crosky-Merritt | I12: De'Von Achane | J12: Bhayshul Tuten | K12: Darnell Mooney
A13: ROUND 11 | B13: Harrison Butker | C13: Colston Loveland | D13: Josh Downs | E13: Kansas City | F13: Tyler Bass | G13: DeAndre Hopkins | H13: Austin Ekeler | I13: Cameron Dicker | J13: Cedric Tillman | K13: David Njoku
A14: ROUND 12 | B14: Baltimore | C14: Tre' Harris | D14: Jake Bates | E14: Joshua Palmer | F14: Philadelphia | G14: Baker Mayfield | H14: Brian Robinson Jr | I14: Jayden Reed | J14: Dak Prescott | K14: Denver
... A17: ROUND 15 | B17: Nick Chubb | C17: Sam LaPorta | D17: Jameson Williams | E17: Adam Thielen | F17: Puka Nacua | G17: Calvin Ridley | H17: Chase Brown | I17: Keenan Allen | J17: Tyreek Hill | K17: Bucky Irving

Sheet 2025 Keepers
B1: 2025 Keepers
B2: Nick Huge Ditka | C2: Tom White Pool Covers | D2: Steve Bed Bath & Bijan | E2: Jon Dumpster Fire | F2: Cory/Kevin Jimmy Jones Cutlets | G2: Ben Prestige Worldwide | H2: Jordan JR | I2: Mike Run CMC | J2: Rick Terry Glenn | K2: Eric My Ball Zach Ertz
